Workbook

Sheet FBDescriptions
A1: Filename | B1: Fuelbed name | C1: Fuelbed description
A2: FB_0029_FCCS | B2: Interior ponderosa pine-Engelmann spruce-Douglas-fir forest | C2: Ponderosa pine, Douglas-fir, and Engelmann spruce are common associates in the mixed conifer forests of the U.S. Rocky Mountains and the Southwest. Large diameter trees have been thinned in this fuelbed, and slash was left on site.
A3: FB_0046_FCCS | B3: Chamise chaparral shrubland | C3: This chaparral type is mostly restricted to coastal mountain areas south from San Diego County north to interior Mendocino County in California, covering more than 1.5 million acres. At lower elevations, chamise (Adenostoma fasciculatum) is found with coastal sage shrubs. At higher elevations, chamise is codominant with arctostaphylos or ceanothus or both.
A4: FB_0066_FCCS | B4: Bluebunch wheatgrass-bluegrass grassland | C4: Prairie grasslands occur throughout the Midwest. This prairie is a mixed-grass prairie that is transitional between short and tall grass prairies in South Dakota. Historically, fire occurred at intervals of less than 35 years.
A5: FB_0067_FCCS | B5: Interior ponderosa pine-Douglas-fir forest | C5: Mixed Douglas-fir and ponderosa pine conifer forests of the northern U.S. Rocky Mountains. Fire exclusion has created elevated levels of hazardous fuels.
A6: FB_0069_FCCS | B6: Western juniper/sagebrush-bitterbrush shrubland | C6: This eastern Oregon site has a mix of sagebrush (Artemesia spp.) and bitterbrush (Purshia tridentata) with scattered western juniper. Fire exclusion has resulted in western juniper encroachment into the sagebrush assemblage. Sagebrush shrublands are widespread throughout the Great Basin, with juniper woodlands above them in elevation and grasslands below.
A7: FB_0071_FCCS | B7: Ohia/Florida hopbush-kupaoa forest | C7: Ohia is the sole tree in this dry broadleaf woodland of the Hawaiian submontane zone. Understories consisting of mixed microphyllous shrubs and grasses are common in this woodland. Ohia woodlands are widely distributed throughout Hawaii at elevations between 1,000 and 4,000 feet.
A8: FB_0077_FCCS | B8: Eucalyptus plantation forest | C8: This fuelbed represents the eucalyptus plantations common in Hawaii.
A9: FB_0087_FCCS | B9: Black spruce/feathermoss forest | C9: Black spruce forest fuelbed with a feathermoss forest floor, between 50 and 150 years old. Found on floodplains and uplands in interior and southcentral Alaska. This fuelbed is comparable to the closed black spruce forest of Viereck et al. (1992).
A10: FB_0109_FCCS | B10: Eastern white pine-northern red oak-red maple forest | C10: Eastern white pine and northern red oak are dominant with red maple as a common canopy associate. Northern hardwood species such as beech, birch, ash, and sugar maple may also be present. This forest type extends through New England west and south along the Appalachian Mountains, typically lower than 3,000 feet in elevation. This fuelbed represents a forest from 50 to 100 years old.
A11: FB_0125_FCCS | B11: Oak-hickory-pine-eastern hemlock forest | C11: Oak -- hickory -- pine -- eastern hemlock forest occur on dissected hills and valleys, from about 300 to 600 feet in elevation. Eastern hemlock occurs predominately in moist coves and along north-facing slopes while pine species occur on drier sites.
A12: FB_0165_FCCS | B12: Longleaf pine/three-awned grass-pitcher plant savanna | C12: Mesic to wet savannas with very open, scattered longleaf pine over a diverse herbaceous layer dominated by grasses and many forb species, 2-3 years after prescribed fire. History of periodic prescribed fire maintains herbaceous layer diversity by reducing cover native and nonative understory shrubs and trees.
... A15: FB_0291_FCCS | B15: Longleaf-slash pine/saw palmetto forest | C15: Longleaf pine, slash pine, and saw palmetto (Serenoa repens) forest resulting from fire exclusion occur throughout the Southeast coastal plain from Virginia south to Florida and west to into Texas. This forest type is characterized by a dense overstory of longleaf pine and slash pine and a very dense shrub layer dominated by saw palmetto. Saw palmetto is less important or absent from these forests in the Carolinas and Virginia. Fire has been excluded for 30 years.

Sheet Definitions
A1: Time Steps | B1: Definitions | C1: Notes
A2: 1 | B2: Immediately post fire
A3: 2 | B3: 2-5 yr post disturbance or 0-3 yrs for Hawaii and SE US | C3: Update rules modify Time Step 1 fuelbeds
A4: 3 | B4: 5-10 yr post disturbance or 3-10 yr for Hawaii and SE US | C4: Update rules modify Time Step 2 fuelbeds
A6: Codes | B6: Disturbance | C6: Severity | D6: Time Step
A7: 511 | B7: Insect | C7: Low | D7: 1
A8: 512 | B8: Insect | C8: Low | D8: 2
A9: 513 | B9: Insect | C9: Low | D9: 3
A10: 521 | B10: Insect | C10: Moderate | D10: 1
A11: 522 | B11: Insect | C11: Moderate | D11: 2
A12: 523 | B12: Insect | C12: Moderate | D12: 3
A13: 531 | B13: Insect | C13: High | D13: 1
A14: 532 | B14: Insect | C14: High | D14: 2
A15: 533 | B15: Insect | C15: High | D15: 3
A17: Issues to discuss
A18: 1) Rules at least by region (western, southern, northeastern, Lake States, boreal)
A19: 2) How to best apply to non-forest vegetation (new scripts likely needed)
A20: 3) We didn't include optional fuel loadings.
A22: Global rule sets:
A23: * Capped percent cover and percent live at 100%
A24: * Specs page is grabbed as is and then convered into expressions within the code
A25: * Snags have their own separate code to accommodate more complicated rule sets
A26: * The Expected tab contains cell references to expected values and is used to ensure the script results match the spreadsheet

Sheet ExtraVars
A1: Extra variables that I did not use in the disturbance update
A2: eCANOPY_SNAGS_CLASS_1_ALL_OTHERS_SPECIES_SPECIES_DESCRIPTION
A3: eCANOPY_SNAGS_CLASS_1_CONIFERS_WITH_FOLIAGE_SPECIES_SPECIES_DESCRIPTION
A4: eCANOPY_SNAGS_CLASS_2_SPECIES_SPECIES_DESCRIPTION
A5: eCANOPY_SNAGS_CLASS_3_SPECIES_SPECIES_DESCRIPTION
A6: eCANOPY_TREES_MIDSTORY_SPECIES_SPECIES_DESCRIPTION
A7: eCANOPY_TREES_OVERSTORY_SPECIES_SPECIES_DESCRIPTION
A8: eCANOPY_TREES_UNDERSTORY_SPECIES_SPECIES_DESCRIPTION
A9: eFUELBED_NAME
A10: eFUELBED_NUMBER
A11: eHERBACEOUS_PRIMARY_LAYER_SPECIES_SPECIES_DESCRIPTION
A12: eHERBACEOUS_SECONDARY_LAYER_SPECIES_SPECIES_DESCRIPTION
... A20: eWOODY_FUEL_STUMPS_SOUND_SPECIES_SPECIES_DESCRIPTION

Sheet 2_MechAdd_Script
B1: Suggested Short Name | C1: 211 | D1: 212 | E1: 213 | F1: 221 | G1: 222 | H1: 223 | I1: 231 | J1: 232 | K1: 233
A2: eCANOPY_TREES_TOTAL_PERCENT_COVER | B2: Canopy_TotalCover | C2: * = 0.85 | F2: * = 0.67 | I2: * = 0.33
A3: eCANOPY_TREES_OVERSTORY_DIAMETER_AT_BREAST_HEIGHT | B3: OTree_Diameter | C3: * = 1.1 | F3: * = 1.25 | I3: * = 1.25
A4: eCANOPY_TREES_OVERSTORY_HEIGHT_TO_LIVE_CROWN | B4: OTree_HeightLiveCrown | C4: * = 1.25 | F4: * = 1.5 | I4: * = 1.5
A5: eCANOPY_TREES_OVERSTORY_HEIGHT | B5: OTree_Height
A6: eCANOPY_TREES_OVERSTORY_PERCENT_COVER | B6: OTree_Cover | C6: * = 0.75 | F6: * = 0.5 | I6: * = 0.25
A7: eCANOPY_TREES_OVERSTORY_STEM_DENSITY | B7: OTree_Density | C7: * = 0.75 | F7: * = 0.5 | I7: * = 0.25
A8: eCANOPY_TREES_MIDSTORY_DIAMETER_AT_BREAST_HEIGHT | B8: MTree_Diameter | C8: * = 1.1 | F8: * = 1.25 | I8: * = 1.25
A9: eCANOPY_TREES_MIDSTORY_HEIGHT_TO_LIVE_CROWN | B9: MTree_HeightLiveCrown | C9: * = 1.25 | F9: * = 1.5 | I9: * = 1.5
A10: eCANOPY_TREES_MIDSTORY_HEIGHT | B10: MTree_Height
A11: eCANOPY_TREES_MIDSTORY_PERCENT_COVER | B11: MTree_Cover | C11: * = 0.75 | F11: * = 0.5 | I11: * = 0.25
A12: eCANOPY_TREES_MIDSTORY_STEM_DENSITY | B12: MTree_Density | C12: * = 0.75 | F12: * = 0.5 | I12: * = 0.25
A13: eCANOPY_TREES_UNDERSTORY_DIAMETER_AT_BREAST_HEIGHT | B13: UTree_Diameter | F13: * = 0 | I13: * = 0
A14: eCANOPY_TREES_UNDERSTORY_HEIGHT_TO_LIVE_CROWN | B14: UTree_HeightLiveCrown | F14: * = 0 | I14: * = 0
A15: eCANOPY_TREES_UNDERSTORY_HEIGHT | B15: UTree_Height | F15: * = 0 | I15: * = 0
A16: eCANOPY_TREES_UNDERSTORY_PERCENT_COVER | B16: UTree_Cover | C16: * = 0.25 | F16: * = 0 | I16: * = 0
A17: eCANOPY_TREES_UNDERSTORY_STEM_DENSITY | B17: UTree_Density | C17: * = 0.25 | F17: * = 0 | I17: * = 0
A18: eCANOPY_SNAGS_CLASS_1_ALL_OTHERS_DIAMETER | B18: C1Snag_Diameter
A19: eCANOPY_SNAGS_CLASS_1_ALL_OTHERS_HEIGHT | B19: C1Snag_Height
A20: eCANOPY_SNAGS_CLASS_1_ALL_OTHERS_STEM_DENSITY | B20: C1Snag_Density
A21: eCANOPY_SNAGS_CLASS_1_CONIFERS_WITH_FOLIAGE_HEIGHT_TO_CROWN_BASE | B21: C1FSnag_HeightCrownBase
A22: eCANOPY_SNAGS_CLASS_1_CONIFERS_WITH_FOLIAGE_DIAMETER | B22: C1FSnag_Diameter
A23: eCANOPY_SNAGS_CLASS_1_CONIFERS_WITH_FOLIAGE_HEIGHT | B23: C1FSnag_Height
A24: eCANOPY_SNAGS_CLASS_1_CONIFERS_WITH_FOLIAGE_PERCENT_COVER | B24: C1FSnag_Cover
A25: eCANOPY_SNAGS_CLASS_1_CONIFERS_WITH_FOLIAGE_STEM_DENSITY | B25: C1FSnag_Density
A26: eCANOPY_SNAGS_CLASS_2_DIAMETER | B26: C2Snag_Diameter
A27: eCANOPY_SNAGS_CLASS_2_HEIGHT | B27: C2Snag_Height
A28: eCANOPY_SNAGS_CLASS_2_STEM_DENSITY | B28: C2Snag_Density
A29: eCANOPY_SNAGS_CLASS_3_DIAMETER | B29: C3Snag_Diameter
... A34: eSHRUBS_PRIMARY_LAYER_HEIGHT | B34: 1Shrub_Height
A35: eSHRUBS_PRIMARY_LAYER_PERCENT_COVER | B35: 1Shrub_Cover | C35: * = 0.75 | D35: * = 1.1 | E35: * = 1.1 | F35: * = 0.5 | G35: * = 1.25 | H35: * = 1.25 | I35: * = 0.25 | J35: * = 1.5 | K35: * = 1.5
A36: eSHRUBS_PRIMARY_LAYER_PERCENT_LIVE | B36: 1Shrub_Live | C36: * = 0.5 | D36: * = 1/0.5 | F36: * = 0.25 | G36: * = 1/0.25 | I36: * = 0.25 | J36: * = 1/0.25
A37: eSHRUBS_SECONDARY_LAYER_HEIGHT | B37: 2Shrub_Height
A38: eSHRUBS_SECONDARY_LAYER_PERCENT_COVER | B38: 2Shrub_Cover | C38: * = 0.75 | D38: * = 1.1 | E38: * = 1.1 | F38: * = 0.5 | G38: * = 1.25 | H38: * = 1.25 | I38: * = 0.25 | J38: * = 1.5 | K38: * = 1.5
A39: eSHRUBS_SECONDARY_LAYER_PERCENT_LIVE | B39: 2Shrub_Live | C39: * = 0.5 | D39: * = 1/0.5 | F39: * = 0.25 | G39: * = 1/0.25 | I39: * = 0.25 | J39: * = 1/0.25
A40: eHERBACEOUS_PRIMARY_LAYER_HEIGHT | B40: 1Herb_Height
A41: eHERBACEOUS_PRIMARY_LAYER_LOADING | B41: 1Herb_Load | C41: * = 0.75 | D41: * = 1.25 | E41: * = 1.25 | F41: * = 0.5 | G41: * = 1.5 | H41: * = 1.5 | I41: * = 0.25 | J41: * = 1.5 | K41: * = 1.5
A42: eHERBACEOUS_PRIMARY_LAYER_PERCENT_COVER | B42: 1Herb_Cover | C42: * = 0.75 | D42: * = 1.25 | E42: * = 1.25 | F42: * = 0.5 | G42: * = 1.5 | H42: * = 1.5 | I42: * = 0.25 | J42: * = 1.5 | K42: * = 1.5
A43: eHERBACEOUS_PRIMARY_LAYER_PERCENT_LIVE | B43: 1Herb_Live | C43: * = 0.75 | D43: * = 1/0.75 | F43: * = 0.5 | G43: * = 1/0.5 | I43: * = 0.25 | J43: * = 1/0.25
A44: eHERBACEOUS_SECONDARY_LAYER_HEIGHT | B44: 2Herb_Height
...

Sheet BaseValues
A1: Variable | B1: FB_0029_FCCS | C1: FB_0046_FCCS | D1: FB_0066_FCCS | E1: FB_0087_FCCS | F1: FB_0109_FCCS | G1: FB_0291_FCCS | I1: FB_0067_FCCS | J1: FB_0069_FCCS | K1: FB_0071_FCCS | L1: FB_0077_FCCS | M1: FB_0125_FCCS | N1: FB_0165_FCCS | O1: FB_0170_FCCS | P1: FB_0175_FCCS
A2: eCANOPY_TREES_TOTAL_PERCENT_COVER | B2: 40 | E2: 80 | F2: 85 | G2: 60 | I2: 50 | J2: 2 | K2: 25 | L2: 84 | M2: 85 | N2: 5 | O2: 20
A3: eCANOPY_TREES_OVERSTORY_DIAMETER_AT_BREAST_HEIGHT | B3: 9.6 | E3: 2.9 | F3: 14 | G3: 12 | I3: 27 | J3: 2.8 | K3: 10.6 | L3: 29 | M3: 17 | N3: 12 | O3: 6
A4: eCANOPY_TREES_OVERSTORY_HEIGHT_TO_LIVE_CROWN | B4: 20 | E4: 4 | F4: 20 | G4: 55 | I4: 55 | J4: 0.8 | K4: 13.2 | L4: 68 | M4: 60 | N4: 45 | O4: 10.5
A5: eCANOPY_TREES_OVERSTORY_HEIGHT | B5: 100 | E5: 25 | F5: 60 | G5: 78 | I5: 105 | J5: 7.2 | K5: 34.7 | L5: 110 | M5: 100 | N5: 70 | O5: 25
A6: eCANOPY_TREES_OVERSTORY_PERCENT_COVER | B6: 40 | E6: 80 | F6: 50 | G6: 50 | I6: 20 | J6: 1 | K6: 21 | L6: 20 | M6: 55 | N6: 5 | O6: 20
A7: eCANOPY_TREES_OVERSTORY_STEM_DENSITY | B7: 12 | E7: 3500 | F7: 45 | G7: 100 | I7: 17 | J7: 36 | K7: 106 | L7: 15 | M7: 75 | N7: 15 | O7: 60
A8: eCANOPY_TREES_MIDSTORY_DIAMETER_AT_BREAST_HEIGHT | F8: 7.5 | I8: 10 | L8: 14 | M8: 6 | N8: 8
A9: eCANOPY_TREES_MIDSTORY_HEIGHT_TO_LIVE_CROWN | F9: 10 | I9: 28 | L9: 25 | M9: 40 | N9: 15
A10: eCANOPY_TREES_MIDSTORY_HEIGHT | F10: 44 | I10: 58 | L10: 54 | M10: 60 | N10: 20
A11: eCANOPY_TREES_MIDSTORY_PERCENT_COVER | F11: 50 | I11: 40 | L11: 40 | M11: 40 | N11: 5
A12: eCANOPY_TREES_MIDSTORY_STEM_DENSITY | F12: 150 | I12: 153 | L12: 100 | M12: 150 | N12: 10
A13: eCANOPY_TREES_UNDERSTORY_DIAMETER_AT_BREAST_HEIGHT | E13: 0.5 | F13: 1.7 | G13: 1 | J13: 0.4 | L13: 5 | M13: 2 | O13: 0
A14: eCANOPY_TREES_UNDERSTORY_HEIGHT_TO_LIVE_CROWN | E14: 0 | F14: 2 | G14: 2 | J14: 0.1 | L14: 12 | M14: 4 | O14: 1
A15: eCANOPY_TREES_UNDERSTORY_HEIGHT | E15: 1.5 | F15: 10 | G15: 5 | J15: 0.9 | L15: 27.5 | M15: 15 | O15: 3
A16: eCANOPY_TREES_UNDERSTORY_PERCENT_COVER | E16: 3 | F16: 30 | G16: 5 | J16: 1 | L16: 40 | M16: 20 | O16: 3
A17: eCANOPY_TREES_UNDERSTORY_STEM_DENSITY | E17: 1000 | F17: 1000 | G17: 25 | J17: 108 | L17: 700 | M17: 300 | O17: 40
A18: eCANOPY_SNAGS_CLASS_1_ALL_OTHERS_DIAMETER | E18: 3.5 | F18: 13 | M18: 7
A19: eCANOPY_SNAGS_CLASS_1_ALL_OTHERS_HEIGHT | E19: 25 | F19: 55 | M19: 45
A20: eCANOPY_SNAGS_CLASS_1_ALL_OTHERS_STEM_DENSITY | E20: 100 | F20: 5 | M20: 15
A21: eCANOPY_SNAGS_CLASS_1_CONIFERS_WITH_FOLIAGE_HEIGHT_TO_CROWN_BASE | F21: 33.35 | I21: 47.36 | M21: 33.35
A22: eCANOPY_SNAGS_CLASS_1_CONIFERS_WITH_FOLIAGE_DIAMETER | F22: 9 | I22: 20.6 | M22: 9
A23: eCANOPY_SNAGS_CLASS_1_CONIFERS_WITH_FOLIAGE_HEIGHT | F23: 50 | I23: 71 | M23: 50
A24: eCANOPY_SNAGS_CLASS_1_CONIFERS_WITH_FOLIAGE_PERCENT_COVER | F24: 0.5071 | I24: 1.43152 | M24: 0.10142
A25: eCANOPY_SNAGS_CLASS_1_CONIFERS_WITH_FOLIAGE_STEM_DENSITY | F25: 5 | I25: 7 | M25: 1
A26: eCANOPY_SNAGS_CLASS_2_DIAMETER | E26: 3.5 | F26: 11 | G26: 12 | I26: 20.6 | L26: 11.3 | M26: 7 | O26: 5
A27: eCANOPY_SNAGS_CLASS_2_HEIGHT | E27: 20 | F27: 50 | G27: 70 | I27: 65 | L27: 51.3 | M27: 40 | O27: 20
A28: eCANOPY_SNAGS_CLASS_2_STEM_DENSITY | E28: 150 | F28: 10 | G28: 3 | I28: 7 | L28: 5 | M28: 15 | O28: 4
A29: eCANOPY_SNAGS_CLASS_3_DIAMETER | B29: 9 | E29: 3.5 | F29: 11 | G29: 10 | I29: 20.6 | L29: 11.3 | M29: 7 | O29: 5
A30: eCANOPY_SNAGS_CLASS_3_HEIGHT | B30: 60 | E30: 15 | F30: 40 | G30: 60 | I30: 50 | L30: 26 | M30: 20 | O30: 15
A31: eCANOPY_SNAGS_CLASS_3_STEM_DENSITY | B31: 3 | E31: 150 | F31: 5 | G31: 3 | I31: 7 | L31: 60 | M31: 15 | O31: 3
A32: eCANOPY_LADDER_FUELS_MAXIMUM_HEIGHT | E32: 4 | F32: 15 | I32: 58 | L32: 50
A33: eCANOPY_LADDER_FUELS_MINIMUM_HEIGHT | E33: 0 | F33: 5 | I33: 28 | L33: 5
A34: eSHRUBS_PRIMARY_LAYER_HEIGHT | B34: 2.2 | C34: 5 | D34: 3 | E34: 5 | F34: 6 | G34: 5 | I34: 5 | J34: 1.7 | K34: 3.9 | L34: 3.1 | M34: 10 | N34: 10 | O34: 3.5
A35: eSHRUBS_PRIMARY_LAYER_PERCENT_COVER | B35: 21.6 | C35: 70 | D35: 2 | E35: 10 | F35: 30 | G35: 80 | I35: 60 | J35: 40 | K35: 33 | L35: 8 | M35: 25 | N35: 10 | O35: 85
A36: eSHRUBS_PRIMARY_LAYER_PERCENT_LIVE | B36: 85 | C36: 85 | D36: 100 | E36: 90 | F36: 85 | G36: 90 | I36: 90 | J36: 93 | K36: 80 | L36: 90 | M36: 85 | N36: 80 | O36: 90
A37: eSHRUBS_PRIMARY_LAYER_LOADING
A38: eSHRUBS_SECONDARY_LAYER_HEIGHT | B38: 0.3 | C38: 2 | E38: 1 | M38: 2.5 | N38: 4 | O38: 5
A39: eSHRUBS_SECONDARY_LAYER_PERCENT_COVER | B39: 1.2 | C39: 5 | E39: 20 | M39: 20 | N39: 15 | O39: 30
A40: eSHRUBS_SECONDARY_LAYER_PERCENT_LIVE | B40: 95 | C40: 85 | E40: 90 | M40: 85 | N40: 80 | O40: 90
...

Sheet 2_MechAdd_LowSeverity
A1: Variable | B1: Suggested Short Name | C1: Time Step 1 (211) Rules | D1: Time Step 2 (212) Rules | E1: Time Step 3 (213) Rules | F1: FB_0029_FCCS | G1: FB_0029_FCCS_211 | H1: FB_0029_FCCS_212 | I1: FB_0029_FCCS_213 | J1: FB_0046_FCCS | K1: FB_0046_FCCS_211 | L1: FB_0046_FCCS_212 | M1: FB_0046_FCCS_213 | N1: FB_0066_FCCS | O1: FB_0066_FCCS_211 | P1: FB_0066_FCCS_212 | Q1: FB_0066_FCCS_213 | R1: FB_0087_FCCS | S1: FB_0087_FCCS_211 | T1: FB_0087_FCCS_212 | U1: FB_0087_FCCS_213 | V1: FB_0109_FCCS | W1: FB_0109_FCCS_211 | X1: FB_0109_FCCS_212 | Y1: FB_0109_FCCS_213 | Z1: FB_0291_FCCS | AA1: FB_0291_FCCS_211 | AB1: FB_0291_FCCS_212 | AC1: FB_0291_FCCS_213
A2: ='2_MechAdd_Script'!A2 | B2: Canopy_TotalCover | C2: 0.85 | F2: 40 | G2: =$C2*F2 | H2: =G2 | I2: =H2 | K2: =$C2*J2 | L2: =K2 | M2: =L2 | O2: =$C2*N2 | P2: =O2 | Q2: =P2 | R2: 80 | S2: =$C2*R2 | T2: =S2 | U2: =T2 | V2: 85 | W2: =$C2*V2 | X2: =W2 | Y2: =X2 | Z2: 60 | AA2: =$C2*Z2 | AB2: =AA2 | AC2: =AB2
A3: ='2_MechAdd_Script'!A3 | B3: OTree_Diameter | C3: 1.1 | F3: 9.6 | G3: =$C3*F3 | H3: =G3 | I3: =H3 | K3: =$C3*J3 | L3: =K3 | M3: =L3 | O3: =$C3*N3 | P3: =O3 | Q3: =P3 | R3: 2.9 | S3: =$C3*R3 | T3: =S3 | U3: =T3 | V3: 14 | W3: =$C3*V3 | X3: =W3 | Y3: =X3 | Z3: 12 | AA3: =$C3*Z3 | AB3: =AA3 | AC3: =AB3
A4: ='2_MechAdd_Script'!A4 | B4: OTree_HeightLiveCrown | C4: 1.25 | F4: 20 | G4: =$C4*F4 | H4: =G4 | I4: =H4 | K4: =$C4*J4 | L4: =K4 | M4: =L4 | O4: =$C4*N4 | P4: =O4 | Q4: =P4 | R4: 4 | S4: =$C4*R4 | T4: =S4 | U4: =T4 | V4: 20 | W4: =$C4*V4 | X4: =W4 | Y4: =X4 | Z4: 55 | AA4: =$C4*Z4 | AB4: =AA4 | AC4: =AB4
A5: ='2_MechAdd_Script'!A5 | B5: OTree_Height | F5: 100 | G5: =F5 | H5: =G5 | I5: =H5 | K5: =J5 | L5: =K5 | M5: =L5 | O5: =N5 | P5: =O5 | Q5: =P5 | R5: 25 | S5: =R5 | T5: =S5 | U5: =T5 | V5: 60 | W5: =V5 | X5: =W5 | Y5: =X5 | Z5: 78 | AA5: =Z5 | AB5: =AA5 | AC5: =AB5
A6: ='2_MechAdd_Script'!A6 | B6: OTree_Cover | C6: 0.75 | F6: 40 | G6: =$C6*F6 | H6: =G6 | I6: =H6 | K6: =$C6*J6 | L6: =K6 | M6: =L6 | O6: =$C6*N6 | P6: =O6 | Q6: =P6 | R6: 80 | S6: =$C6*R6 | T6: =S6 | U6: =T6 | V6: 50 | W6: =$C6*V6 | X6: =W6 | Y6: =X6 | Z6: 50 | AA6: =$C6*Z6 | AB6: =AA6 | AC6: =AB6
A7: ='2_MechAdd_Script'!A7 | B7: OTree_Density | C7: 0.75 | F7: 12 | G7: =$C7*F7 | H7: =G7 | I7: =H7 | K7: =$C7*J7 | L7: =K7 | M7: =L7 | O7: =$C7*N7 | P7: =O7 | Q7: =P7 | R7: 3500 | S7: =$C7*R7 | T7: =S7 | U7: =T7 | V7: 45 | W7: =$C7*V7 | X7: =W7 | Y7: =X7 | Z7: 100 | AA7: =$C7*Z7 | AB7: =AA7 | AC7: =AB7
A8: ='2_MechAdd_Script'!A8 | B8: MTree_Diameter | C8: 1.1 | G8: =$C8*F8 | H8: =G8 | I8: =H8 | K8: =$C8*J8 | L8: =K8 | M8: =L8 | O8: =$C8*N8 | P8: =O8 | Q8: =P8 | S8: =$C8*R8 | T8: =S8 | U8: =T8 | V8: 7.5 | W8: =$C8*V8 | X8: =W8 | Y8: =X8 | AA8: =$C8*Z8 | AB8: =AA8 | AC8: =AB8
A9: ='2_MechAdd_Script'!A9 | B9: MTree_HeightLiveCrown | C9: 1.25 | G9: =$C9*F9 | H9: =G9 | I9: =H9 | K9: =$C9*J9 | L9: =K9 | M9: =L9 | O9: =$C9*N9 | P9: =O9 | Q9: =P9 | S9: =$C9*R9 | T9: =S9 | U9: =T9 | V9: 10 | W9: =$C9*V9 | X9: =W9 | Y9: =X9 | AA9: =$C9*Z9 | AB9: =AA9 | AC9: =AB9
A10: ='2_MechAdd_Script'!A10 | B10: MTree_Height | G10: =F10 | H10: =G10 | I10: =H10 | K10: =J10 | L10: =K10 | M10: =L10 | O10: =N10 | P10: =O10 | Q10: =P10 | S10: =R10 | T10: =S10 | U10: =T10 | V10: 44 | W10: =V10 | X10: =W10 | Y10: =X10 | AA10: =Z10 | AB10: =AA10 | AC10: =AB10
A11: ='2_MechAdd_Script'!A11 | B11: MTree_Cover | C11: 0.75 | G11: =$C11*F11 | H11: =G11 | I11: =H11 | K11: =$C11*J11 | L11: =K11 | M11: =L11 | O11: =$C11*N11 | P11: =O11 | Q11: =P11 | S11: =$C11*R11 | T11: =S11 | U11: =T11 | V11: 50 | W11: =$C11*V11 | X11: =W11 | Y11: =X11 | AA11: =$C11*Z11 | AB11: =AA11 | AC11: =AB11
A12: ='2_MechAdd_Script'!A12 | B12: MTree_Density | C12: 0.75 | G12: =$C12*F12 | H12: =G12 | I12: =H12 | K12: =$C12*J12 | L12: =K12 | M12: =L12 | O12: =$C12*N12 | P12: =O12 | Q12: =P12 | S12: =$C12*R12 | T12: =S12 | U12: =T12 | V12: 150 | W12: =$C12*V12 | X12: =W12 | Y12: =X12 | AA12: =$C12*Z12 | AB12: =AA12 | AC12: =AB12
A13: ='2_MechAdd_Script'!A13 | B13: UTree_Diameter | G13: =F13 | H13: =G13 | I13: =H13 | K13: =J13 | L13: =K13 | M13: =L13 | O13: =N13 | P13: =O13 | Q13: =P13 | R13: 0.5 | S13: =R13 | T13: =S13 | U13: =T13 | V13: 1.7 | W13: =V13 | X13: =W13 | Y13: =X13 | Z13: 1 | AA13: =Z13 | AB13: =AA13 | AC13: =AB13
A14: ='2_MechAdd_Script'!A14 | B14: UTree_HeightLiveCrown | G14: =F14 | H14: =G14 | I14: =H14 | K14: =J14 | L14: =K14 | M14: =L14 | O14: =N14 | P14: =O14 | Q14: =P14 | R14: 0 | S14: =R14 | T14: =S14 | U14: =T14 | V14: 2 | W14: =V14 | X14: =W14 | Y14: =X14 | Z14: 2 | AA14: =Z14 | AB14: =AA14 | AC14: =AB14
A15: ='2_MechAdd_Script'!A15 | B15: UTree_Height | G15: =F15 | H15: =G15 | I15: =H15 | K15: =J15 | L15: =K15 | M15: =L15 | O15: =N15 | P15: =O15 | Q15: =P15 | R15: 1.5 | S15: =R15 | T15: =S15 | U15: =T15 | V15: 10 | W15: =V15 | X15: =W15 | Y15: =X15 | Z15: 5 | AA15: =Z15 | AB15: =AA15 | AC15: =AB15
A16: ='2_MechAdd_Script'!A16 | B16: UTree_Cover | C16: 0.25 | G16: =$C16*F16 | H16: =G16 | I16: =H16 | K16: =$C16*J16 | L16: =K16 | M16: =L16 | O16: =$C16*N16 | P16: =O16 | Q16: =P16 | R16: 3 | S16: =$C16*R16 | T16: =S16 | U16: =T16 | V16: 30 | W16: =$C16*V16 | X16: =W16 | Y16: =X16 | Z16: 5 | AA16: =$C16*Z16 | AB16: =AA16 | AC16: =AB16
A17: ='2_MechAdd_Script'!A17 | B17: UTree_Density | C17: 0.25 | G17: =$C17*F17 | H17: =G17 | I17: =H17 | K17: =$C17*J17 | L17: =K17 | M17: =L17 | O17: =$C17*N17 | P17: =O17 | Q17: =P17 | R17: 1000 | S17: =$C17*R17 | T17: =S17 | U17: =T17 | V17: 1000 | W17: =$C17*V17 | X17: =W17 | Y17: =X17 | Z17: 25 | AA17: =$C17*Z17 | AB17: =AA17 | AC17: =AB17
A18: ='2_MechAdd_Script'!A18 | B18: C1Snag_Diameter | G18: =F18 | H18: =G18 | I18: =H18 | K18: =J18 | L18: =K18 | M18: =L18 | O18: =N18 | P18: =O18 | Q18: =P18 | R18: 3.5 | S18: =R18 | T18: =S18 | U18: =T18 | V18: 13 | W18: =V18 | X18: =W18 | Y18: =X18 | AA18: =Z18 | AB18: =AA18 | AC18: =AB18
A19: ='2_MechAdd_Script'!A19 | B19: C1Snag_Height | G19: =F19 | H19: =G19 | I19: =H19 | K19: =J19 | L19: =K19 | M19: =L19 | O19: =N19 | P19: =O19 | Q19: =P19 | R19: 25 | S19: =R19 | T19: =S19 | U19: =T19 | V19: 55 | W19: =V19 | X19: =W19 | Y19: =X19 | AA19: =Z19 | AB19: =AA19 | AC19: =AB19
A20: ='2_MechAdd_Script'!A20 | B20: C1Snag_Density | G20: =F20 | H20: =G20 | I20: =H20 | K20: =J20 | L20: =K20 | M20: =L20 | O20: =N20 | P20: =O20 | Q20: =P20 | R20: 100 | S20: =R20 | T20: =S20 | U20: =T20 | V20: 5 | W20: =V20 | X20: =W20 | Y20: =X20 | AA20: =Z20 | AB20: =AA20 | AC20: =AB20
A21: ='2_MechAdd_Script'!A21 | B21: C1FSnag_HeightCrownBase | G21: =F21 | H21: =G21 | I21: =H21 | K21: =J21 | L21: =K21 | M21: =L21 | O21: =N21 | P21: =O21 | Q21: =P21 | S21: =R21 | T21: =S21 | U21: =T21 | V21: 33.35 | W21: =V21 | X21: =W21 | Y21: =X21 | AA21: =Z21 | AB21: =AA21 | AC21: =AB21
A22: ='2_MechAdd_Script'!A22 | B22: C1FSnag_Diameter | G22: =F22 | H22: =G22 | I22: =H22 | K22: =J22 | L22: =K22 | M22: =L22 | O22: =N22 | P22: =O22 | Q22: =P22 | S22: =R22 | T22: =S22 | U22: =T22 | V22: 9 | W22: =V22 | X22: =W22 | Y22: =X22 | AA22: =Z22 | AB22: =AA22 | AC22: =AB22
A23: ='2_MechAdd_Script'!A23 | B23: C1FSnag_Height | G23: =F23 | H23: =G23 | I23: =H23 | K23: =J23 | L23: =K23 | M23: =L23 | O23: =N23 | P23: =O23 | Q23: =P23 | S23: =R23 | T23: =S23 | U23: =T23 | V23: 50 | W23: =V23 | X23: =W23 | Y23: =X23 | AA23: =Z23 | AB23: =AA23 | AC23: =AB23
A24: ='2_MechAdd_Script'!A24 | B24: C1FSnag_Cover | G24: =F24 | H24: =G24 | I24: =H24 | K24: =J24 | L24: =K24 | M24: =L24 | O24: =N24 | P24: =O24 | Q24: =P24 | S24: =R24 | T24: =S24 | U24: =T24 | V24: 0.5071 | W24: =V24 | X24: =W24 | Y24: =X24 | AA24: =Z24 | AB24: =AA24 | AC24: =AB24
A25: ='2_MechAdd_Script'!A25 | B25: C1FSnag_Density | G25: =F25 | H25: =G25 | I25: =H25 | K25: =J25 | L25: =K25 | M25: =L25 | O25: =N25 | P25: =O25 | Q25: =P25 | S25: =R25 | T25: =S25 | U25: =T25 | V25: 5 | W25: =V25 | X25: =W25 | Y25: =X25 | AA25: =Z25 | AB25: =AA25 | AC25: =AB25
A26: ='2_MechAdd_Script'!A26 | B26: C2Snag_Diameter | G26: =F26 | H26: =G26 | I26: =H26 | K26: =J26 | L26: =K26 | M26: =L26 | O26: =N26 | P26: =O26 | Q26: =P26 | R26: 3.5 | S26: =R26 | T26: =S26 | U26: =T26 | V26: 11 | W26: =V26 | X26: =W26 | Y26: =X26 | Z26: 12 | AA26: =Z26 | AB26: =AA26 | AC26: =AB26
A27: ='2_MechAdd_Script'!A27 | B27: C2Snag_Height | G27: =F27 | H27: =G27 | I27: =H27 | K27: =J27 | L27: =K27 | M27: =L27 | O27: =N27 | P27: =O27 | Q27: =P27 | R27: 20 | S27: =R27 | T27: =S27 | U27: =T27 | V27: 50 | W27: =V27 | X27: =W27 | Y27: =X27 | Z27: 70 | AA27: =Z27 | AB27: =AA27 | AC27: =AB27
A28: ='2_MechAdd_Script'!A28 | B28: C2Snag_Density | G28: =F28 | H28: =G28 | I28: =H28 | K28: =J28 | L28: =K28 | M28: =L28 | O28: =N28 | P28: =O28 | Q28: =P28 | R28: 150 | S28: =R28 | T28: =S28 | U28: =T28 | V28: 10 | W28: =V28 | X28: =W28 | Y28: =X28 | Z28: 3 | AA28: =Z28 | AB28: =AA28 | AC28: =AB28
A29: ='2_MechAdd_Script'!A29 | B29: C3Snag_Diameter | F29: 9 | G29: =F29 | H29: =G29 | I29: =H29 | K29: =J29 | L29: =K29 | M29: =L29 | O29: =N29 | P29: =O29 | Q29: =P29 | R29: 3.5 | S29: =R29 | T29: =S29 | U29: =T29 | V29: 11 | W29: =V29 | X29: =W29 | Y29: =X29 | Z29: 10 | AA29: =Z29 | AB29: =AA29 | AC29: =AB29
A30: ='2_MechAdd_Script'!A30 | B30: C3Snag_Height | F30: 60 | G30: =F30 | H30: =G30 | I30: =H30 | K30: =J30 | L30: =K30 | M30: =L30 | O30: =N30 | P30: =O30 | Q30: =P30 | R30: 15 | S30: =R30 | T30: =S30 | U30: =T30 | V30: 40 | W30: =V30 | X30: =W30 | Y30: =X30 | Z30: 60 | AA30: =Z30 | AB30: =AA30 | AC30: =AB30
A31: ='2_MechAdd_Script'!A31 | B31: C3Snag_Density | F31: 3 | G31: =F31 | H31: =G31 | I31: =H31 | K31: =J31 | L31: =K31 | M31: =L31 | O31: =N31 | P31: =O31 | Q31: =P31 | R31: 150 | S31: =R31 | T31: =S31 | U31: =T31 | V31: 5 | W31: =V31 | X31: =W31 | Y31: =X31 | Z31: 3 | AA31: =Z31 | AB31: =AA31 | AC31: =AB31
A32: ='2_MechAdd_Script'!A32 | B32: Ladder_MaxHeight | G32: =F32 | H32: =G32 | I32: =H32 | K32: =J32 | L32: =K32 | M32: =L32 | O32: =N32 | P32: =O32 | Q32: =P32 | R32: 4 | S32: =R32 | T32: =S32 | U32: =T32 | V32: 15 | W32: =V32 | X32: =W32 | Y32: =X32 | AA32: =Z32 | AB32: =AA32 | AC32: =AB32
A33: ='2_MechAdd_Script'!A33 | B33: Ladder_MinHeight | G33: =F33 | H33: =G33 | I33: =H33 | K33: =J33 | L33: =K33 | M33: =L33 | O33: =N33 | P33: =O33 | Q33: =P33 | R33: 0 | S33: =R33 | T33: =S33 | U33: =T33 | V33: 5 | W33: =V33 | X33: =W33 | Y33: =X33 | AA33: =Z33 | AB33: =AA33 | AC33: =AB33
A34: ='2_MechAdd_Script'!A34 | B34: 1Shrub_Height | F34: 2.2 | G34: =F34 | H34: =G34 | I34: =H34 | J34: 5 | K34: =J34 | L34: =K34 | M34: =L34 | N34: 3 | O34: =N34 | P34: =O34 | Q34: =P34 | R34: 5 | S34: =R34 | T34: =S34 | U34: =T34 | V34: 6 | W34: =V34 | X34: =W34 | Y34: =X34 | Z34: 5 | AA34: =Z34 | AB34: =AA34 | AC34: =AB34
A35: ='2_MechAdd_Script'!A35 | B35: 1Shrub_Cover | C35: 0.75 | D35: 1.1 | E35: 1.1 | F35: 21.6 | G35: =$C35*F35 | H35: =MIN(100,G35*$D35) | I35: =MIN(100,$E35*H35) | J35: 70 | K35: =$C35*J35 | L35: =MIN(100,K35*$D35) | M35: =MIN(100,$E35*L35) | N35: 2 | O35: =$C35*N35 | P35: =MIN(100,O35*$D35) | Q35: =MIN(100,$E35*P35) | R35: 10 | S35: =$C35*R35 | T35: =MIN(100,S35*$D35) | U35: =MIN(100,$E35*T35) | V35: 30 | W35: =$C35*V35 | X35: =MIN(100,W35*$D35) | Y35: =MIN(100,$E35*X35) | Z35: 80 | AA35: =$C35*Z35 | AB35: =MIN(100,AA35*$D35) | AC35: =MIN(100,$E35*AB35)
A36: ='2_MechAdd_Script'!A36 | B36: 1Shrub_Live | C36: 0.5 | D36: =1/0.5 | F36: 85 | G36: =$C36*F36 | H36: =MIN(100,G36*$D36) | I36: =H36 | J36: 85 | K36: =$C36*J36 | L36: =MIN(100,K36*$D36) | M36: =L36 | N36: 100 | O36: =$C36*N36 | P36: =MIN(100,O36*$D36) | Q36: =P36 | R36: 90 | S36: =$C36*R36 | T36: =MIN(100,S36*$D36) | U36: =T36 | V36: 85 | W36: =$C36*V36 | X36: =MIN(100,W36*$D36) | Y36: =X36 | Z36: 90 | AA36: =$C36*Z36 | AB36: =MIN(100,AA36*$D36) | AC36: =AB36
A37: ='2_MechAdd_Script'!A37 | B37: 2Shrub_Height | F37: 0.3 | G37: =F37 | H37: =G37 | I37: =H37 | J37: 2 | K37: =J37 | L37: =K37 | M37: =L37 | O37: =N37 | P37: =O37 | Q37: =P37 | R37: 1 | S37: =R37 | T37: =S37 | U37: =T37 | W37: =V37 | X37: =W37 | Y37: =X37 | AA37: =Z37 | AB37: =AA37 | AC37: =AB37
A38: ='2_MechAdd_Script'!A38 | B38: 2Shrub_Cover | C38: 0.75 | D38: 1.1 | E38: 1.1 | F38: 1.2 | G38: =$C38*F38 | H38: =MIN(100,G38*$D38) | I38: =MIN(100,$E38*H38) | J38: 5 | K38: =$C38*J38 | L38: =MIN(100,K38*$D38) | M38: =MIN(100,$E38*L38) | O38: =$C38*N38 | P38: =MIN(100,O38*$D38) | Q38: =MIN(100,$E38*P38) | R38: 20 | S38: =$C38*R38 | T38: =MIN(100,S38*$D38) | U38: =MIN(100,$E38*T38) | W38: =$C38*V38 | X38: =MIN(100,W38*$D38) | Y38: =MIN(100,$E38*X38) | AA38: =$C38*Z38 | AB38: =MIN(100,AA38*$D38) | AC38: =MIN(100,$E38*AB38)
A39: ='2_MechAdd_Script'!A39 | B39: 2Shrub_Live | C39: 0.5 | D39: =1/0.5 | F39: 95 | G39: =$C39*F39 | H39: =MIN(100,G39*$D39) | I39: =H39 | J39: 85 | K39: =$C39*J39 | L39: =MIN(100,K39*$D39) | M39: =L39 | O39: =$C39*N39 | P39: =MIN(100,O39*$D39) | Q39: =P39 | R39: 90 | S39: =$C39*R39 | T39: =MIN(100,S39*$D39) | U39: =T39 | W39: =$C39*V39 | X39: =MIN(100,W39*$D39) | Y39: =X39 | AA39: =$C39*Z39 | AB39: =MIN(100,AA39*$D39) | AC39: =AB39
A40: ='2_MechAdd_Script'!A40 | B40: 1Herb_Height | F40: 0.9 | G40: =F40 | H40: =G40 | I40: =H40 | K40: =J40 | L40: =K40 | M40: =L40 | N40: 2 | O40: =N40 | P40: =O40 | Q40: =P40 | R40: 1 | S40: =R40 | T40: =S40 | U40: =T40 | V40: 2.5 | W40: =V40 | X40: =W40 | Y40: =X40 | Z40: 2 | AA40: =Z40 | AB40: =AA40 | AC40: =AB40
...

Sheet 2_MechAdd_ModSeverity
A1: Variable | B1: Suggested Short Name | C1: Mod Time Step 1 (221) Rules | D1: Time Step 2 (222) Rules | E1: Time Step 3 (223) Rules | F1: FB_0029_FCCS | G1: FB_0029_FCCS_221 | H1: FB_0029_FCCS_222 | I1: FB_0029_FCCS_223 | J1: FB_0046_FCCS | K1: FB_0046_FCCS_221 | L1: FB_0046_FCCS_222 | M1: FB_0046_FCCS_223 | N1: FB_0066_FCCS | O1: FB_0066_FCCS_221 | P1: FB_0066_FCCS_222 | Q1: FB_0066_FCCS_223 | R1: FB_0087_FCCS | S1: FB_0087_FCCS_221 | T1: FB_0087_FCCS_222 | U1: FB_0087_FCCS_223 | V1: FB_0109_FCCS | W1: FB_0109_FCCS_221 | X1: FB_0109_FCCS_222 | Y1: FB_0109_FCCS_223 | Z1: FB_0291_FCCS | AA1: FB_0291_FCCS_221 | AB1: FB_0291_FCCS_222 | AC1: FB_0291_FCCS_223
A2: ='2_MechAdd_Script'!A2 | B2: Canopy_TotalCover | C2: 0.67 | F2: 40 | G2: =$C2*F2 | H2: =G2 | I2: =H2 | K2: =$C2*J2 | L2: =K2 | M2: =L2 | O2: =$C2*N2 | P2: =O2 | Q2: =P2 | R2: 80 | S2: =$C2*R2 | T2: =S2 | U2: =T2 | V2: 85 | W2: =$C2*V2 | X2: =W2 | Y2: =X2 | Z2: 60 | AA2: =$C2*Z2 | AB2: =AA2 | AC2: =AB2
A3: ='2_MechAdd_Script'!A3 | B3: OTree_Diameter | C3: 1.25 | F3: 9.6 | G3: =$C3*F3 | H3: =G3 | I3: =H3 | K3: =$C3*J3 | L3: =K3 | M3: =L3 | O3: =$C3*N3 | P3: =O3 | Q3: =P3 | R3: 2.9 | S3: =$C3*R3 | T3: =S3 | U3: =T3 | V3: 14 | W3: =$C3*V3 | X3: =W3 | Y3: =X3 | Z3: 12 | AA3: =$C3*Z3 | AB3: =AA3 | AC3: =AB3
A4: ='2_MechAdd_Script'!A4 | B4: OTree_HeightLiveCrown | C4: 1.5 | F4: 20 | G4: =$C4*F4 | H4: =G4 | I4: =H4 | K4: =$C4*J4 | L4: =K4 | M4: =L4 | O4: =$C4*N4 | P4: =O4 | Q4: =P4 | R4: 4 | S4: =$C4*R4 | T4: =S4 | U4: =T4 | V4: 20 | W4: =$C4*V4 | X4: =W4 | Y4: =X4 | Z4: 55 | AA4: =$C4*Z4 | AB4: =AA4 | AC4: =AB4
A5: ='2_MechAdd_Script'!A5 | B5: OTree_Height | F5: 100 | G5: =F5 | H5: =G5 | I5: =H5 | K5: =J5 | L5: =K5 | M5: =L5 | O5: =N5 | P5: =O5 | Q5: =P5 | R5: 25 | S5: =R5 | T5: =S5 | U5: =T5 | V5: 60 | W5: =V5 | X5: =W5 | Y5: =X5 | Z5: 78 | AA5: =Z5 | AB5: =AA5 | AC5: =AB5
A6: ='2_MechAdd_Script'!A6 | B6: OTree_Cover | C6: 0.5 | F6: 40 | G6: =$C6*F6 | H6: =G6 | I6: =H6 | K6: =$C6*J6 | L6: =K6 | M6: =L6 | O6: =$C6*N6 | P6: =O6 | Q6: =P6 | R6: 80 | S6: =$C6*R6 | T6: =S6 | U6: =T6 | V6: 50 | W6: =$C6*V6 | X6: =W6 | Y6: =X6 | Z6: 50 | AA6: =$C6*Z6 | AB6: =AA6 | AC6: =AB6
A7: ='2_MechAdd_Script'!A7 | B7: OTree_Density | C7: 0.5 | F7: 12 | G7: =$C7*F7 | H7: =G7 | I7: =H7 | K7: =$C7*J7 | L7: =K7 | M7: =L7 | O7: =$C7*N7 | P7: =O7 | Q7: =P7 | R7: 3500 | S7: =$C7*R7 | T7: =S7 | U7: =T7 | V7: 45 | W7: =$C7*V7 | X7: =W7 | Y7: =X7 | Z7: 100 | AA7: =$C7*Z7 | AB7: =AA7 | AC7: =AB7
A8: ='2_MechAdd_Script'!A8 | B8: MTree_Diameter | C8: 1.25 | G8: =$C8*F8 | H8: =G8 | I8: =H8 | K8: =$C8*J8 | L8: =K8 | M8: =L8 | O8: =$C8*N8 | P8: =O8 | Q8: =P8 | S8: =$C8*R8 | T8: =S8 | U8: =T8 | V8: 7.5 | W8: =$C8*V8 | X8: =W8 | Y8: =X8 | AA8: =$C8*Z8 | AB8: =AA8 | AC8: =AB8
A9: ='2_MechAdd_Script'!A9 | B9: MTree_HeightLiveCrown | C9: 1.5 | G9: =$C9*F9 | H9: =G9 | I9: =H9 | K9: =$C9*J9 | L9: =K9 | M9: =L9 | O9: =$C9*N9 | P9: =O9 | Q9: =P9 | S9: =$C9*R9 | T9: =S9 | U9: =T9 | V9: 10 | W9: =$C9*V9 | X9: =W9 | Y9: =X9 | AA9: =$C9*Z9 | AB9: =AA9 | AC9: =AB9
A10: ='2_MechAdd_Script'!A10 | B10: MTree_Height | G10: =F10 | H10: =G10 | I10: =H10 | K10: =J10 | L10: =K10 | M10: =L10 | O10: =N10 | P10: =O10 | Q10: =P10 | S10: =R10 | T10: =S10 | U10: =T10 | V10: 44 | W10: =V10 | X10: =W10 | Y10: =X10 | AA10: =Z10 | AB10: =AA10 | AC10: =AB10
A11: ='2_MechAdd_Script'!A11 | B11: MTree_Cover | C11: 0.5 | G11: =$C11*F11 | H11: =G11 | I11: =H11 | K11: =$C11*J11 | L11: =K11 | M11: =L11 | O11: =$C11*N11 | P11: =O11 | Q11: =P11 | S11: =$C11*R11 | T11: =S11 | U11: =T11 | V11: 50 | W11: =$C11*V11 | X11: =W11 | Y11: =X11 | AA11: =$C11*Z11 | AB11: =AA11 | AC11: =AB11
A12: ='2_MechAdd_Script'!A12 | B12: MTree_Density | C12: 0.5 | G12: =$C12*F12 | H12: =G12 | I12: =H12 | K12: =$C12*J12 | L12: =K12 | M12: =L12 | O12: =$C12*N12 | P12: =O12 | Q12: =P12 | S12: =$C12*R12 | T12: =S12 | U12: =T12 | V12: 150 | W12: =$C12*V12 | X12: =W12 | Y12: =X12 | AA12: =$C12*Z12 | AB12: =AA12 | AC12: =AB12
A13: ='2_MechAdd_Script'!A13 | B13: UTree_Diameter | C13: 0 | G13: =$C13*F13 | H13: =G13 | I13: =H13 | K13: =$C13*J13 | L13: =K13 | M13: =L13 | O13: =$C13*N13 | P13: =O13 | Q13: =P13 | R13: 0.5 | S13: =$C13*R13 | T13: =S13 | U13: =T13 | V13: 1.7 | W13: =$C13*V13 | X13: =W13 | Y13: =X13 | Z13: 1 | AA13: =$C13*Z13 | AB13: =AA13 | AC13: =AB13
A14: ='2_MechAdd_Script'!A14 | B14: UTree_HeightLiveCrown | C14: 0 | G14: =$C14*F14 | H14: =G14 | I14: =H14 | K14: =$C14*J14 | L14: =K14 | M14: =L14 | O14: =$C14*N14 | P14: =O14 | Q14: =P14 | R14: 0 | S14: =$C14*R14 | T14: =S14 | U14: =T14 | V14: 2 | W14: =$C14*V14 | X14: =W14 | Y14: =X14 | Z14: 2 | AA14: =$C14*Z14 | AB14: =AA14 | AC14: =AB14
A15: ='2_MechAdd_Script'!A15 | B15: UTree_Height | C15: 0 | G15: =$C15*F15 | H15: =G15 | I15: =H15 | K15: =$C15*J15 | L15: =K15 | M15: =L15 | O15: =$C15*N15 | P15: =O15 | Q15: =P15 | R15: 1.5 | S15: =$C15*R15 | T15: =S15 | U15: =T15 | V15: 10 | W15: =$C15*V15 | X15: =W15 | Y15: =X15 | Z15: 5 | AA15: =$C15*Z15 | AB15: =AA15 | AC15: =AB15
A16: ='2_MechAdd_Script'!A16 | B16: UTree_Cover | C16: 0 | G16: =$C16*F16 | H16: =G16 | I16: =H16 | K16: =$C16*J16 | L16: =K16 | M16: =L16 | O16: =$C16*N16 | P16: =O16 | Q16: =P16 | R16: 3 | S16: =$C16*R16 | T16: =S16 | U16: =T16 | V16: 30 | W16: =$C16*V16 | X16: =W16 | Y16: =X16 | Z16: 5 | AA16: =$C16*Z16 | AB16: =AA16 | AC16: =AB16
A17: ='2_MechAdd_Script'!A17 | B17: UTree_Density | C17: 0 | G17: =$C17*F17 | H17: =G17 | I17: =H17 | K17: =$C17*J17 | L17: =K17 | M17: =L17 | O17: =$C17*N17 | P17: =O17 | Q17: =P17 | R17: 1000 | S17: =$C17*R17 | T17: =S17 | U17: =T17 | V17: 1000 | W17: =$C17*V17 | X17: =W17 | Y17: =X17 | Z17: 25 | AA17: =$C17*Z17 | AB17: =AA17 | AC17: =AB17
A18: ='2_MechAdd_Script'!A18 | B18: C1Snag_Diameter | G18: =F18 | H18: =G18 | I18: =H18 | K18: =J18 | L18: =K18 | M18: =L18 | O18: =N18 | P18: =O18 | Q18: =P18 | R18: 3.5 | S18: =R18 | T18: =S18 | U18: =T18 | V18: 13 | W18: =V18 | X18: =W18 | Y18: =X18 | AA18: =Z18 | AB18: =AA18 | AC18: =AB18
A19: ='2_MechAdd_Script'!A19 | B19: C1Snag_Height | G19: =F19 | H19: =G19 | I19: =H19 | K19: =J19 | L19: =K19 | M19: =L19 | O19: =N19 | P19: =O19 | Q19: =P19 | R19: 25 | S19: =R19 | T19: =S19 | U19: =T19 | V19: 55 | W19: =V19 | X19: =W19 | Y19: =X19 | AA19: =Z19 | AB19: =AA19 | AC19: =AB19
A20: ='2_MechAdd_Script'!A20 | B20: C1Snag_Density | G20: =F20 | H20: =G20 | I20: =H20 | K20: =J20 | L20: =K20 | M20: =L20 | O20: =N20 | P20: =O20 | Q20: =P20 | R20: 100 | S20: =R20 | T20: =S20 | U20: =T20 | V20: 5 | W20: =V20 | X20: =W20 | Y20: =X20 | AA20: =Z20 | AB20: =AA20 | AC20: =AB20
A21: ='2_MechAdd_Script'!A21 | B21: C1FSnag_HeightCrownBase | G21: =F21 | H21: =G21 | I21: =H21 | K21: =J21 | L21: =K21 | M21: =L21 | O21: =N21 | P21: =O21 | Q21: =P21 | S21: =R21 | T21: =S21 | U21: =T21 | V21: 33.35 | W21: =V21 | X21: =W21 | Y21: =X21 | AA21: =Z21 | AB21: =AA21 | AC21: =AB21
A22: ='2_MechAdd_Script'!A22 | B22: C1FSnag_Diameter | G22: =F22 | H22: =G22 | I22: =H22 | K22: =J22 | L22: =K22 | M22: =L22 | O22: =N22 | P22: =O22 | Q22: =P22 | S22: =R22 | T22: =S22 | U22: =T22 | V22: 9 | W22: =V22 | X22: =W22 | Y22: =X22 | AA22: =Z22 | AB22: =AA22 | AC22: =AB22
A23: ='2_MechAdd_Script'!A23 | B23: C1FSnag_Height | G23: =F23 | H23: =G23 | I23: =H23 | K23: =J23 | L23: =K23 | M23: =L23 | O23: =N23 | P23: =O23 | Q23: =P23 | S23: =R23 | T23: =S23 | U23: =T23 | V23: 50 | W23: =V23 | X23: =W23 | Y23: =X23 | AA23: =Z23 | AB23: =AA23 | AC23: =AB23
A24: ='2_MechAdd_Script'!A24 | B24: C1FSnag_Cover | G24: =F24 | H24: =G24 | I24: =H24 | K24: =J24 | L24: =K24 | M24: =L24 | O24: =N24 | P24: =O24 | Q24: =P24 | S24: =R24 | T24: =S24 | U24: =T24 | V24: 0.5071 | W24: =V24 | X24: =W24 | Y24: =X24 | AA24: =Z24 | AB24: =AA24 | AC24: =AB24
A25: ='2_MechAdd_Script'!A25 | B25: C1FSnag_Density | G25: =F25 | H25: =G25 | I25: =H25 | K25: =J25 | L25: =K25 | M25: =L25 | O25: =N25 | P25: =O25 | Q25: =P25 | S25: =R25 | T25: =S25 | U25: =T25 | V25: 5 | W25: =V25 | X25: =W25 | Y25: =X25 | AA25: =Z25 | AB25: =AA25 | AC25: =AB25
A26: ='2_MechAdd_Script'!A26 | B26: C2Snag_Diameter | G26: =F26 | H26: =G26 | I26: =H26 | K26: =J26 | L26: =K26 | M26: =L26 | O26: =N26 | P26: =O26 | Q26: =P26 | R26: 3.5 | S26: =R26 | T26: =S26 | U26: =T26 | V26: 11 | W26: =V26 | X26: =W26 | Y26: =X26 | Z26: 12 | AA26: =Z26 | AB26: =AA26 | AC26: =AB26
A27: ='2_MechAdd_Script'!A27 | B27: C2Snag_Height | G27: =F27 | H27: =G27 | I27: =H27 | K27: =J27 | L27: =K27 | M27: =L27 | O27: =N27 | P27: =O27 | Q27: =P27 | R27: 20 | S27: =R27 | T27: =S27 | U27: =T27 | V27: 50 | W27: =V27 | X27: =W27 | Y27: =X27 | Z27: 70 | AA27: =Z27 | AB27: =AA27 | AC27: =AB27
A28: ='2_MechAdd_Script'!A28 | B28: C2Snag_Density | G28: =F28 | H28: =G28 | I28: =H28 | K28: =J28 | L28: =K28 | M28: =L28 | O28: =N28 | P28: =O28 | Q28: =P28 | R28: 150 | S28: =R28 | T28: =S28 | U28: =T28 | V28: 10 | W28: =V28 | X28: =W28 | Y28: =X28 | Z28: 3 | AA28: =Z28 | AB28: =AA28 | AC28: =AB28
A29: ='2_MechAdd_Script'!A29 | B29: C3Snag_Diameter | F29: 9 | G29: =F29 | H29: =G29 | I29: =H29 | K29: =J29 | L29: =K29 | M29: =L29 | O29: =N29 | P29: =O29 | Q29: =P29 | R29: 3.5 | S29: =R29 | T29: =S29 | U29: =T29 | V29: 11 | W29: =V29 | X29: =W29 | Y29: =X29 | Z29: 10 | AA29: =Z29 | AB29: =AA29 | AC29: =AB29
A30: ='2_MechAdd_Script'!A30 | B30: C3Snag_Height | F30: 60 | G30: =F30 | H30: =G30 | I30: =H30 | K30: =J30 | L30: =K30 | M30: =L30 | O30: =N30 | P30: =O30 | Q30: =P30 | R30: 15 | S30: =R30 | T30: =S30 | U30: =T30 | V30: 40 | W30: =V30 | X30: =W30 | Y30: =X30 | Z30: 60 | AA30: =Z30 | AB30: =AA30 | AC30: =AB30
A31: ='2_MechAdd_Script'!A31 | B31: C3Snag_Density | F31: 3 | G31: =F31 | H31: =G31 | I31: =H31 | K31: =J31 | L31: =K31 | M31: =L31 | O31: =N31 | P31: =O31 | Q31: =P31 | R31: 150 | S31: =R31 | T31: =S31 | U31: =T31 | V31: 5 | W31: =V31 | X31: =W31 | Y31: =X31 | Z31: 3 | AA31: =Z31 | AB31: =AA31 | AC31: =AB31
A32: ='2_MechAdd_Script'!A32 | B32: Ladder_MaxHeight | G32: =F32 | H32: =G32 | I32: =H32 | K32: =J32 | L32: =K32 | M32: =L32 | O32: =N32 | P32: =O32 | Q32: =P32 | R32: 4 | S32: =R32 | T32: =S32 | U32: =T32 | V32: 15 | W32: =V32 | X32: =W32 | Y32: =X32 | AA32: =Z32 | AB32: =AA32 | AC32: =AB32
A33: ='2_MechAdd_Script'!A33 | B33: Ladder_MinHeight | G33: =F33 | H33: =G33 | I33: =H33 | K33: =J33 | L33: =K33 | M33: =L33 | O33: =N33 | P33: =O33 | Q33: =P33 | R33: 0 | S33: =R33 | T33: =S33 | U33: =T33 | V33: 5 | W33: =V33 | X33: =W33 | Y33: =X33 | AA33: =Z33 | AB33: =AA33 | AC33: =AB33
A34: ='2_MechAdd_Script'!A34 | B34: 1Shrub_Height | F34: 2.2 | G34: =F34 | H34: =G34 | I34: =H34 | J34: 5 | K34: =J34 | L34: =K34 | M34: =L34 | N34: 3 | O34: =N34 | P34: =O34 | Q34: =P34 | R34: 5 | S34: =R34 | T34: =S34 | U34: =T34 | V34: 6 | W34: =V34 | X34: =W34 | Y34: =X34 | Z34: 5 | AA34: =Z34 | AB34: =AA34 | AC34: =AB34
A35: ='2_MechAdd_Script'!A35 | B35: 1Shrub_Cover | C35: 0.5 | D35: 1.25 | E35: 1.25 | F35: 21.6 | G35: =$C35*F35 | H35: =MIN(100,G35*$D35) | I35: =MIN(100,$E35*H35) | J35: 70 | K35: =$C35*J35 | L35: =MIN(100,K35*$D35) | M35: =MIN(100,$E35*L35) | N35: 2 | O35: =$C35*N35 | P35: =MIN(100,O35*$D35) | Q35: =MIN(100,$E35*P35) | R35: 10 | S35: =$C35*R35 | T35: =MIN(100,S35*$D35) | U35: =MIN(100,$E35*T35) | V35: 30 | W35: =$C35*V35 | X35: =MIN(100,W35*$D35) | Y35: =MIN(100,$E35*X35) | Z35: 80 | AA35: =$C35*Z35 | AB35: =MIN(100,AA35*$D35) | AC35: =MIN(100,$E35*AB35)
A36: ='2_MechAdd_Script'!A36 | B36: 1Shrub_Live | C36: 0.25 | D36: =1/0.25 | F36: 85 | G36: =$C36*F36 | H36: =MIN(100,G36*$D36) | I36: =H36 | J36: 85 | K36: =$C36*J36 | L36: =MIN(100,K36*$D36) | M36: =L36 | N36: 100 | O36: =$C36*N36 | P36: =MIN(100,O36*$D36) | Q36: =P36 | R36: 90 | S36: =$C36*R36 | T36: =MIN(100,S36*$D36) | U36: =T36 | V36: 85 | W36: =$C36*V36 | X36: =MIN(100,W36*$D36) | Y36: =X36 | Z36: 90 | AA36: =$C36*Z36 | AB36: =MIN(100,AA36*$D36) | AC36: =AB36
A37: ='2_MechAdd_Script'!A37 | B37: 2Shrub_Height | F37: 0.3 | G37: =F37 | H37: =G37 | I37: =H37 | J37: 2 | K37: =J37 | L37: =K37 | M37: =L37 | O37: =N37 | P37: =O37 | Q37: =P37 | R37: 1 | S37: =R37 | T37: =S37 | U37: =T37 | W37: =V37 | X37: =W37 | Y37: =X37 | AA37: =Z37 | AB37: =AA37 | AC37: =AB37
A38: ='2_MechAdd_Script'!A38 | B38: 2Shrub_Cover | C38: 0.5 | D38: 1.25 | E38: 1.25 | F38: 1.2 | G38: =$C38*F38 | H38: =MIN(100,G38*$D38) | I38: =MIN(100,$E38*H38) | J38: 5 | K38: =$C38*J38 | L38: =MIN(100,K38*$D38) | M38: =MIN(100,$E38*L38) | O38: =$C38*N38 | P38: =MIN(100,O38*$D38) | Q38: =MIN(100,$E38*P38) | R38: 20 | S38: =$C38*R38 | T38: =MIN(100,S38*$D38) | U38: =MIN(100,$E38*T38) | W38: =$C38*V38 | X38: =MIN(100,W38*$D38) | Y38: =MIN(100,$E38*X38) | AA38: =$C38*Z38 | AB38: =MIN(100,AA38*$D38) | AC38: =MIN(100,$E38*AB38)
A39: ='2_MechAdd_Script'!A39 | B39: 2Shrub_Live | C39: 0.25 | D39: =1/0.25 | F39: 95 | G39: =$C39*F39 | H39: =MIN(100,G39*$D39) | I39: =H39 | J39: 85 | K39: =$C39*J39 | L39: =MIN(100,K39*$D39) | M39: =L39 | O39: =$C39*N39 | P39: =MIN(100,O39*$D39) | Q39: =P39 | R39: 90 | S39: =$C39*R39 | T39: =MIN(100,S39*$D39) | U39: =T39 | W39: =$C39*V39 | X39: =MIN(100,W39*$D39) | Y39: =X39 | AA39: =$C39*Z39 | AB39: =MIN(100,AA39*$D39) | AC39: =AB39
A40: ='2_MechAdd_Script'!A40 | B40: 1Herb_Height | F40: 0.9 | G40: =F40 | H40: =G40 | I40: =H40 | K40: =J40 | L40: =K40 | M40: =L40 | N40: 2 | O40: =N40 | P40: =O40 | Q40: =P40 | R40: 1 | S40: =R40 | T40: =S40 | U40: =T40 | V40: 2.5 | W40: =V40 | X40: =W40 | Y40: =X40 | Z40: 2 | AA40: =Z40 | AB40: =AA40 | AC40: =AB40
...

Sheet 2_MechAdd_HighSeverity
A1: Variable | B1: Suggested Short Name | C1: High Time Step 1 (231) Rules | D1: Time Step 2 (232) Rules | E1: Time Step 3 (233) Rules | F1: FB_0029_FCCS | G1: FB_0029_FCCS_231 | H1: FB_0029_FCCS_232 | I1: FB_0029_FCCS_233 | J1: FB_0046_FCCS | K1: FB_0046_FCCS_231 | L1: FB_0046_FCCS_232 | M1: FB_0046_FCCS_233 | N1: FB_0066_FCCS | O1: FB_0066_FCCS_231 | P1: FB_0066_FCCS_232 | Q1: FB_0066_FCCS_233 | R1: FB_0087_FCCS | S1: FB_0087_FCCS_231 | T1: FB_0087_FCCS_232 | U1: FB_0087_FCCS_233 | V1: FB_0109_FCCS | W1: FB_0109_FCCS_231 | X1: FB_0109_FCCS_232 | Y1: FB_0109_FCCS_233 | Z1: FB_0291_FCCS | AA1: FB_0291_FCCS_231 | AB1: FB_0291_FCCS_232 | AC1: FB_0291_FCCS_233
A2: ='2_MechAdd_Script'!A2 | B2: Canopy_TotalCover | C2: 0.33 | F2: 40 | G2: =$C2*F2 | H2: =G2 | I2: =H2 | K2: =$C2*J2 | L2: =K2 | M2: =L2 | O2: =$C2*N2 | P2: =O2 | Q2: =P2 | R2: 80 | S2: =$C2*R2 | T2: =S2 | U2: =T2 | V2: 85 | W2: =$C2*V2 | X2: =W2 | Y2: =X2 | Z2: 60 | AA2: =$C2*Z2 | AB2: =AA2 | AC2: =AB2
A3: ='2_MechAdd_Script'!A3 | B3: OTree_Diameter | C3: 1.25 | F3: 9.6 | G3: =$C3*F3 | H3: =G3 | I3: =H3 | K3: =$C3*J3 | L3: =K3 | M3: =L3 | O3: =$C3*N3 | P3: =O3 | Q3: =P3 | R3: 2.9 | S3: =$C3*R3 | T3: =S3 | U3: =T3 | V3: 14 | W3: =$C3*V3 | X3: =W3 | Y3: =X3 | Z3: 12 | AA3: =$C3*Z3 | AB3: =AA3 | AC3: =AB3
A4: ='2_MechAdd_Script'!A4 | B4: OTree_HeightLiveCrown | C4: 1.5 | F4: 20 | G4: =$C4*F4 | H4: =G4 | I4: =H4 | K4: =$C4*J4 | L4: =K4 | M4: =L4 | O4: =$C4*N4 | P4: =O4 | Q4: =P4 | R4: 4 | S4: =$C4*R4 | T4: =S4 | U4: =T4 | V4: 20 | W4: =$C4*V4 | X4: =W4 | Y4: =X4 | Z4: 55 | AA4: =$C4*Z4 | AB4: =AA4 | AC4: =AB4
A5: ='2_MechAdd_Script'!A5 | B5: OTree_Height | F5: 100 | G5: =F5 | H5: =G5 | I5: =H5 | K5: =J5 | L5: =K5 | M5: =L5 | O5: =N5 | P5: =O5 | Q5: =P5 | R5: 25 | S5: =R5 | T5: =S5 | U5: =T5 | V5: 60 | W5: =V5 | X5: =W5 | Y5: =X5 | Z5: 78 | AA5: =Z5 | AB5: =AA5 | AC5: =AB5
A6: ='2_MechAdd_Script'!A6 | B6: OTree_Cover | C6: 0.25 | F6: 40 | G6: =$C6*F6 | H6: =G6 | I6: =H6 | K6: =$C6*J6 | L6: =K6 | M6: =L6 | O6: =$C6*N6 | P6: =O6 | Q6: =P6 | R6: 80 | S6: =$C6*R6 | T6: =S6 | U6: =T6 | V6: 50 | W6: =$C6*V6 | X6: =W6 | Y6: =X6 | Z6: 50 | AA6: =$C6*Z6 | AB6: =AA6 | AC6: =AB6
A7: ='2_MechAdd_Script'!A7 | B7: OTree_Density | C7: 0.25 | F7: 12 | G7: =$C7*F7 | H7: =G7 | I7: =H7 | K7: =$C7*J7 | L7: =K7 | M7: =L7 | O7: =$C7*N7 | P7: =O7 | Q7: =P7 | R7: 3500 | S7: =$C7*R7 | T7: =S7 | U7: =T7 | V7: 45 | W7: =$C7*V7 | X7: =W7 | Y7: =X7 | Z7: 100 | AA7: =$C7*Z7 | AB7: =AA7 | AC7: =AB7
A8: ='2_MechAdd_Script'!A8 | B8: MTree_Diameter | C8: 1.25 | G8: =$C8*F8 | H8: =G8 | I8: =H8 | K8: =$C8*J8 | L8: =K8 | M8: =L8 | O8: =$C8*N8 | P8: =O8 | Q8: =P8 | S8: =$C8*R8 | T8: =S8 | U8: =T8 | V8: 7.5 | W8: =$C8*V8 | X8: =W8 | Y8: =X8 | AA8: =$C8*Z8 | AB8: =AA8 | AC8: =AB8
A9: ='2_MechAdd_Script'!A9 | B9: MTree_HeightLiveCrown | C9: 1.5 | G9: =$C9*F9 | H9: =G9 | I9: =H9 | K9: =$C9*J9 | L9: =K9 | M9: =L9 | O9: =$C9*N9 | P9: =O9 | Q9: =P9 | S9: =$C9*R9 | T9: =S9 | U9: =T9 | V9: 10 | W9: =$C9*V9 | X9: =W9 | Y9: =X9 | AA9: =$C9*Z9 | AB9: =AA9 | AC9: =AB9
A10: ='2_MechAdd_Script'!A10 | B10: MTree_Height | G10: =F10 | H10: =G10 | I10: =H10 | K10: =J10 | L10: =K10 | M10: =L10 | O10: =N10 | P10: =O10 | Q10: =P10 | S10: =R10 | T10: =S10 | U10: =T10 | V10: 44 | W10: =V10 | X10: =W10 | Y10: =X10 | AA10: =Z10 | AB10: =AA10 | AC10: =AB10
A11: ='2_MechAdd_Script'!A11 | B11: MTree_Cover | C11: 0.25 | G11: =$C11*F11 | H11: =G11 | I11: =H11 | K11: =$C11*J11 | L11: =K11 | M11: =L11 | O11: =$C11*N11 | P11: =O11 | Q11: =P11 | S11: =$C11*R11 | T11: =S11 | U11: =T11 | V11: 50 | W11: =$C11*V11 | X11: =W11 | Y11: =X11 | AA11: =$C11*Z11 | AB11: =AA11 | AC11: =AB11
A12: ='2_MechAdd_Script'!A12 | B12: MTree_Density | C12: 0.25 | G12: =$C12*F12 | H12: =G12 | I12: =H12 | K12: =$C12*J12 | L12: =K12 | M12: =L12 | O12: =$C12*N12 | P12: =O12 | Q12: =P12 | S12: =$C12*R12 | T12: =S12 | U12: =T12 | V12: 150 | W12: =$C12*V12 | X12: =W12 | Y12: =X12 | AA12: =$C12*Z12 | AB12: =AA12 | AC12: =AB12
A13: ='2_MechAdd_Script'!A13 | B13: UTree_Diameter | C13: 0 | G13: =$C13*F13 | H13: =G13 | I13: =H13 | K13: =$C13*J13 | L13: =K13 | M13: =L13 | O13: =$C13*N13 | P13: =O13 | Q13: =P13 | R13: 0.5 | S13: =$C13*R13 | T13: =S13 | U13: =T13 | V13: 1.7 | W13: =$C13*V13 | X13: =W13 | Y13: =X13 | Z13: 1 | AA13: =$C13*Z13 | AB13: =AA13 | AC13: =AB13
A14: ='2_MechAdd_Script'!A14 | B14: UTree_HeightLiveCrown | C14: 0 | G14: =$C14*F14 | H14: =G14 | I14: =H14 | K14: =$C14*J14 | L14: =K14 | M14: =L14 | O14: =$C14*N14 | P14: =O14 | Q14: =P14 | R14: 0 | S14: =$C14*R14 | T14: =S14 | U14: =T14 | V14: 2 | W14: =$C14*V14 | X14: =W14 | Y14: =X14 | Z14: 2 | AA14: =$C14*Z14 | AB14: =AA14 | AC14: =AB14
A15: ='2_MechAdd_Script'!A15 | B15: UTree_Height | C15: 0 | G15: =$C15*F15 | H15: =G15 | I15: =H15 | K15: =$C15*J15 | L15: =K15 | M15: =L15 | O15: =$C15*N15 | P15: =O15 | Q15: =P15 | R15: 1.5 | S15: =$C15*R15 | T15: =S15 | U15: =T15 | V15: 10 | W15: =$C15*V15 | X15: =W15 | Y15: =X15 | Z15: 5 | AA15: =$C15*Z15 | AB15: =AA15 | AC15: =AB15
A16: ='2_MechAdd_Script'!A16 | B16: UTree_Cover | C16: 0 | G16: =$C16*F16 | H16: =G16 | I16: =H16 | K16: =$C16*J16 | L16: =K16 | M16: =L16 | O16: =$C16*N16 | P16: =O16 | Q16: =P16 | R16: 3 | S16: =$C16*R16 | T16: =S16 | U16: =T16 | V16: 30 | W16: =$C16*V16 | X16: =W16 | Y16: =X16 | Z16: 5 | AA16: =$C16*Z16 | AB16: =AA16 | AC16: =AB16
A17: ='2_MechAdd_Script'!A17 | B17: UTree_Density | C17: 0 | G17: =$C17*F17 | H17: =G17 | I17: =H17 | K17: =$C17*J17 | L17: =K17 | M17: =L17 | O17: =$C17*N17 | P17: =O17 | Q17: =P17 | R17: 1000 | S17: =$C17*R17 | T17: =S17 | U17: =T17 | V17: 1000 | W17: =$C17*V17 | X17: =W17 | Y17: =X17 | Z17: 25 | AA17: =$C17*Z17 | AB17: =AA17 | AC17: =AB17
A18: ='2_MechAdd_Script'!A18 | B18: C1Snag_Diameter | G18: =F18 | H18: =G18 | I18: =H18 | K18: =J18 | L18: =K18 | M18: =L18 | O18: =N18 | P18: =O18 | Q18: =P18 | R18: 3.5 | S18: =R18 | T18: =S18 | U18: =T18 | V18: 13 | W18: =V18 | X18: =W18 | Y18: =X18 | AA18: =Z18 | AB18: =AA18 | AC18: =AB18
A19: ='2_MechAdd_Script'!A19 | B19: C1Snag_Height | G19: =F19 | H19: =G19 | I19: =H19 | K19: =J19 | L19: =K19 | M19: =L19 | O19: =N19 | P19: =O19 | Q19: =P19 | R19: 25 | S19: =R19 | T19: =S19 | U19: =T19 | V19: 55 | W19: =V19 | X19: =W19 | Y19: =X19 | AA19: =Z19 | AB19: =AA19 | AC19: =AB19
A20: ='2_MechAdd_Script'!A20 | B20: C1Snag_Density | G20: =F20 | H20: =G20 | I20: =H20 | K20: =J20 | L20: =K20 | M20: =L20 | O20: =N20 | P20: =O20 | Q20: =P20 | R20: 100 | S20: =R20 | T20: =S20 | U20: =T20 | V20: 5 | W20: =V20 | X20: =W20 | Y20: =X20 | AA20: =Z20 | AB20: =AA20 | AC20: =AB20
A21: ='2_MechAdd_Script'!A21 | B21: C1FSnag_HeightCrownBase | G21: =F21 | H21: =G21 | I21: =H21 | K21: =J21 | L21: =K21 | M21: =L21 | O21: =N21 | P21: =O21 | Q21: =P21 | S21: =R21 | T21: =S21 | U21: =T21 | V21: 33.35 | W21: =V21 | X21: =W21 | Y21: =X21 | AA21: =Z21 | AB21: =AA21 | AC21: =AB21
A22: ='2_MechAdd_Script'!A22 | B22: C1FSnag_Diameter | G22: =F22 | H22: =G22 | I22: =H22 | K22: =J22 | L22: =K22 | M22: =L22 | O22: =N22 | P22: =O22 | Q22: =P22 | S22: =R22 | T22: =S22 | U22: =T22 | V22: 9 | W22: =V22 | X22: =W22 | Y22: =X22 | AA22: =Z22 | AB22: =AA22 | AC22: =AB22
A23: ='2_MechAdd_Script'!A23 | B23: C1FSnag_Height | G23: =F23 | H23: =G23 | I23: =H23 | K23: =J23 | L23: =K23 | M23: =L23 | O23: =N23 | P23: =O23 | Q23: =P23 | S23: =R23 | T23: =S23 | U23: =T23 | V23: 50 | W23: =V23 | X23: =W23 | Y23: =X23 | AA23: =Z23 | AB23: =AA23 | AC23: =AB23
A24: ='2_MechAdd_Script'!A24 | B24: C1FSnag_Cover | G24: =F24 | H24: =G24 | I24: =H24 | K24: =J24 | L24: =K24 | M24: =L24 | O24: =N24 | P24: =O24 | Q24: =P24 | S24: =R24 | T24: =S24 | U24: =T24 | V24: 0.5071 | W24: =V24 | X24: =W24 | Y24: =X24 | AA24: =Z24 | AB24: =AA24 | AC24: =AB24
A25: ='2_MechAdd_Script'!A25 | B25: C1FSnag_Density | G25: =F25 | H25: =G25 | I25: =H25 | K25: =J25 | L25: =K25 | M25: =L25 | O25: =N25 | P25: =O25 | Q25: =P25 | S25: =R25 | T25: =S25 | U25: =T25 | V25: 5 | W25: =V25 | X25: =W25 | Y25: =X25 | AA25: =Z25 | AB25: =AA25 | AC25: =AB25
A26: ='2_MechAdd_Script'!A26 | B26: C2Snag_Diameter | G26: =F26 | H26: =G26 | I26: =H26 | K26: =J26 | L26: =K26 | M26: =L26 | O26: =N26 | P26: =O26 | Q26: =P26 | R26: 3.5 | S26: =R26 | T26: =S26 | U26: =T26 | V26: 11 | W26: =V26 | X26: =W26 | Y26: =X26 | Z26: 12 | AA26: =Z26 | AB26: =AA26 | AC26: =AB26
A27: ='2_MechAdd_Script'!A27 | B27: C2Snag_Height | G27: =F27 | H27: =G27 | I27: =H27 | K27: =J27 | L27: =K27 | M27: =L27 | O27: =N27 | P27: =O27 | Q27: =P27 | R27: 20 | S27: =R27 | T27: =S27 | U27: =T27 | V27: 50 | W27: =V27 | X27: =W27 | Y27: =X27 | Z27: 70 | AA27: =Z27 | AB27: =AA27 | AC27: =AB27
A28: ='2_MechAdd_Script'!A28 | B28: C2Snag_Density | G28: =F28 | H28: =G28 | I28: =H28 | K28: =J28 | L28: =K28 | M28: =L28 | O28: =N28 | P28: =O28 | Q28: =P28 | R28: 150 | S28: =R28 | T28: =S28 | U28: =T28 | V28: 10 | W28: =V28 | X28: =W28 | Y28: =X28 | Z28: 3 | AA28: =Z28 | AB28: =AA28 | AC28: =AB28
A29: ='2_MechAdd_Script'!A29 | B29: C3Snag_Diameter | F29: 9 | G29: =F29 | H29: =G29 | I29: =H29 | K29: =J29 | L29: =K29 | M29: =L29 | O29: =N29 | P29: =O29 | Q29: =P29 | R29: 3.5 | S29: =R29 | T29: =S29 | U29: =T29 | V29: 11 | W29: =V29 | X29: =W29 | Y29: =X29 | Z29: 10 | AA29: =Z29 | AB29: =AA29 | AC29: =AB29
A30: ='2_MechAdd_Script'!A30 | B30: C3Snag_Height | F30: 60 | G30: =F30 | H30: =G30 | I30: =H30 | K30: =J30 | L30: =K30 | M30: =L30 | O30: =N30 | P30: =O30 | Q30: =P30 | R30: 15 | S30: =R30 | T30: =S30 | U30: =T30 | V30: 40 | W30: =V30 | X30: =W30 | Y30: =X30 | Z30: 60 | AA30: =Z30 | AB30: =AA30 | AC30: =AB30
A31: ='2_MechAdd_Script'!A31 | B31: C3Snag_Density | F31: 3 | G31: =F31 | H31: =G31 | I31: =H31 | K31: =J31 | L31: =K31 | M31: =L31 | O31: =N31 | P31: =O31 | Q31: =P31 | R31: 150 | S31: =R31 | T31: =S31 | U31: =T31 | V31: 5 | W31: =V31 | X31: =W31 | Y31: =X31 | Z31: 3 | AA31: =Z31 | AB31: =AA31 | AC31: =AB31
A32: ='2_MechAdd_Script'!A32 | B32: Ladder_MaxHeight | G32: =F32 | H32: =G32 | I32: =H32 | K32: =J32 | L32: =K32 | M32: =L32 | O32: =N32 | P32: =O32 | Q32: =P32 | R32: 4 | S32: =R32 | T32: =S32 | U32: =T32 | V32: 15 | W32: =V32 | X32: =W32 | Y32: =X32 | AA32: =Z32 | AB32: =AA32 | AC32: =AB32
A33: ='2_MechAdd_Script'!A33 | B33: Ladder_MinHeight | G33: =F33 | H33: =G33 | I33: =H33 | K33: =J33 | L33: =K33 | M33: =L33 | O33: =N33 | P33: =O33 | Q33: =P33 | R33: 0 | S33: =R33 | T33: =S33 | U33: =T33 | V33: 5 | W33: =V33 | X33: =W33 | Y33: =X33 | AA33: =Z33 | AB33: =AA33 | AC33: =AB33
A34: ='2_MechAdd_Script'!A34 | B34: 1Shrub_Height | F34: 2.2 | G34: =F34 | H34: =G34 | I34: =H34 | J34: 5 | K34: =J34 | L34: =K34 | M34: =L34 | N34: 3 | O34: =N34 | P34: =O34 | Q34: =P34 | R34: 5 | S34: =R34 | T34: =S34 | U34: =T34 | V34: 6 | W34: =V34 | X34: =W34 | Y34: =X34 | Z34: 5 | AA34: =Z34 | AB34: =AA34 | AC34: =AB34
A35: ='2_MechAdd_Script'!A35 | B35: 1Shrub_Cover | C35: 0.25 | D35: 1.5 | E35: 1.5 | F35: 21.6 | G35: =$C35*F35 | H35: =MIN(100,G35*$D35) | I35: =MIN(100,$E35*H35) | J35: 70 | K35: =$C35*J35 | L35: =MIN(100,K35*$D35) | M35: =MIN(100,$E35*L35) | N35: 2 | O35: =$C35*N35 | P35: =MIN(100,O35*$D35) | Q35: =MIN(100,$E35*P35) | R35: 10 | S35: =$C35*R35 | T35: =MIN(100,S35*$D35) | U35: =MIN(100,$E35*T35) | V35: 30 | W35: =$C35*V35 | X35: =MIN(100,W35*$D35) | Y35: =MIN(100,$E35*X35) | Z35: 80 | AA35: =$C35*Z35 | AB35: =MIN(100,AA35*$D35) | AC35: =MIN(100,$E35*AB35)
A36: ='2_MechAdd_Script'!A36 | B36: 1Shrub_Live | C36: 0.25 | D36: =1/0.25 | F36: 85 | G36: =$C36*F36 | H36: =MIN(100,G36*$D36) | I36: =H36 | J36: 85 | K36: =$C36*J36 | L36: =MIN(100,K36*$D36) | M36: =L36 | N36: 100 | O36: =$C36*N36 | P36: =MIN(100,O36*$D36) | Q36: =P36 | R36: 90 | S36: =$C36*R36 | T36: =MIN(100,S36*$D36) | U36: =T36 | V36: 85 | W36: =$C36*V36 | X36: =MIN(100,W36*$D36) | Y36: =X36 | Z36: 90 | AA36: =$C36*Z36 | AB36: =MIN(100,AA36*$D36) | AC36: =AB36
A37: ='2_MechAdd_Script'!A37 | B37: 2Shrub_Height | F37: 0.3 | G37: =F37 | H37: =G37 | I37: =H37 | J37: 2 | K37: =J37 | L37: =K37 | M37: =L37 | O37: =N37 | P37: =O37 | Q37: =P37 | R37: 1 | S37: =R37 | T37: =S37 | U37: =T37 | W37: =V37 | X37: =W37 | Y37: =X37 | AA37: =Z37 | AB37: =AA37 | AC37: =AB37
A38: ='2_MechAdd_Script'!A38 | B38: 2Shrub_Cover | C38: 0.25 | D38: 1.5 | E38: 1.5 | F38: 1.2 | G38: =$C38*F38 | H38: =MIN(100,G38*$D38) | I38: =MIN(100,$E38*H38) | J38: 5 | K38: =$C38*J38 | L38: =MIN(100,K38*$D38) | M38: =MIN(100,$E38*L38) | O38: =$C38*N38 | P38: =MIN(100,O38*$D38) | Q38: =MIN(100,$E38*P38) | R38: 20 | S38: =$C38*R38 | T38: =MIN(100,S38*$D38) | U38: =MIN(100,$E38*T38) | W38: =$C38*V38 | X38: =MIN(100,W38*$D38) | Y38: =MIN(100,$E38*X38) | AA38: =$C38*Z38 | AB38: =MIN(100,AA38*$D38) | AC38: =MIN(100,$E38*AB38)
A39: ='2_MechAdd_Script'!A39 | B39: 2Shrub_Live | C39: 0.25 | D39: =1/0.25 | F39: 95 | G39: =$C39*F39 | H39: =MIN(100,G39*$D39) | I39: =H39 | J39: 85 | K39: =$C39*J39 | L39: =MIN(100,K39*$D39) | M39: =L39 | O39: =$C39*N39 | P39: =MIN(100,O39*$D39) | Q39: =P39 | R39: 90 | S39: =$C39*R39 | T39: =MIN(100,S39*$D39) | U39: =T39 | W39: =$C39*V39 | X39: =MIN(100,W39*$D39) | Y39: =X39 | AA39: =$C39*Z39 | AB39: =MIN(100,AA39*$D39) | AC39: =AB39
A40: ='2_MechAdd_Script'!A40 | B40: 1Herb_Height | F40: 0.9 | G40: =F40 | H40: =G40 | I40: =H40 | K40: =J40 | L40: =K40 | M40: =L40 | N40: 2 | O40: =N40 | P40: =O40 | Q40: =P40 | R40: 1 | S40: =R40 | T40: =S40 | U40: =T40 | V40: 2.5 | W40: =V40 | X40: =W40 | Y40: =X40 | Z40: 2 | AA40: =Z40 | AB40: =AA40 | AC40: =AB40
...

Sheet Expected
A1: Variable | B1: FB_0029_FCCS | C1: FB_0029_FCCS_111 | D1: FB_0029_FCCS_112 | E1: FB_0029_FCCS_113 | F1: FB_0029_FCCS_121 | G1: FB_0029_FCCS_122 | H1: FB_0029_FCCS_123 | I1: FB_0029_FCCS_131 | J1: FB_0029_FCCS_132 | K1: FB_0029_FCCS_133 | L1: FB_0046_FCCS | M1: FB_0046_FCCS_111 | N1: FB_0046_FCCS_112 | O1: FB_0046_FCCS_113 | P1: FB_0046_FCCS_121 | Q1: FB_0046_FCCS_122 | R1: FB_0046_FCCS_123 | S1: FB_0046_FCCS_131 | T1: FB_0046_FCCS_132 | U1: FB_0046_FCCS_133 | V1: FB_0066_FCCS | W1: FB_0066_FCCS_111 | X1: FB_0066_FCCS_112 | Y1: FB_0066_FCCS_113 | Z1: FB_0066_FCCS_121 | AA1: FB_0066_FCCS_122 | AB1: FB_0066_FCCS_123 | AC1: FB_0066_FCCS_131 | AD1: FB_0066_FCCS_132 | AE1: FB_0066_FCCS_133 | AF1: FB_0087_FCCS | AG1: FB_0087_FCCS_111 | AH1: FB_0087_FCCS_112 | AI1: FB_0087_FCCS_113 | AJ1: FB_0087_FCCS_121 | AK1: FB_0087_FCCS_122 | AL1: FB_0087_FCCS_123 | AM1: FB_0087_FCCS_131 | AN1: FB_0087_FCCS_132 | AO1: FB_0087_FCCS_133 | AP1: FB_0109_FCCS | AQ1: FB_0109_FCCS_111 | AR1: FB_0109_FCCS_112 | AS1: FB_0109_FCCS_113 | AT1: FB_0109_FCCS_121 | AU1: FB_0109_FCCS_122 | AV1: FB_0109_FCCS_123 | AW1: FB_0109_FCCS_131 | AX1: FB_0109_FCCS_132 | AY1: FB_0109_FCCS_133 | AZ1: FB_0291_FCCS | BA1: FB_0291_FCCS_111 | BB1: FB_0291_FCCS_112 | BC1: FB_0291_FCCS_113 | BD1: FB_0291_FCCS_121 | BE1: FB_0291_FCCS_122 | BF1: FB_0291_FCCS_123 | BG1: FB_0291_FCCS_131 | BH1: FB_0291_FCCS_132 | BI1: FB_0291_FCCS_133
A2: ='2_MechAdd_Script'!A2 | B2: ='2_MechAdd_LowSeverity'!F2 | C2: ='2_MechAdd_LowSeverity'!G2 | D2: ='2_MechAdd_LowSeverity'!H2 | E2: ='2_MechAdd_LowSeverity'!I2 | F2: ='2_MechAdd_ModSeverity'!G2 | G2: ='2_MechAdd_ModSeverity'!H2 | H2: ='2_MechAdd_ModSeverity'!I2 | I2: ='2_MechAdd_HighSeverity'!G2 | J2: ='2_MechAdd_HighSeverity'!H2 | K2: ='2_MechAdd_HighSeverity'!I2 | L2: ='2_MechAdd_LowSeverity'!J2 | M2: ='2_MechAdd_LowSeverity'!K2 | N2: ='2_MechAdd_LowSeverity'!L2 | O2: ='2_MechAdd_LowSeverity'!M2 | P2: ='2_MechAdd_ModSeverity'!K2 | Q2: ='2_MechAdd_ModSeverity'!L2 | R2: ='2_MechAdd_ModSeverity'!M2 | S2: ='2_MechAdd_HighSeverity'!K2 | T2: ='2_MechAdd_HighSeverity'!L2 | U2: ='2_MechAdd_HighSeverity'!M2 | V2: ='2_MechAdd_LowSeverity'!N2 | W2: ='2_MechAdd_LowSeverity'!O2 | X2: ='2_MechAdd_LowSeverity'!P2 | Y2: ='2_MechAdd_LowSeverity'!Q2 | Z2: ='2_MechAdd_ModSeverity'!O2 | AA2: ='2_MechAdd_ModSeverity'!P2 | AB2: ='2_MechAdd_ModSeverity'!Q2 | AC2: ='2_MechAdd_HighSeverity'!O2 | AD2: ='2_MechAdd_HighSeverity'!P2 | AE2: ='2_MechAdd_HighSeverity'!Q2 | AF2: ='2_MechAdd_LowSeverity'!R2 | AG2: ='2_MechAdd_LowSeverity'!S2 | AH2: ='2_MechAdd_LowSeverity'!T2 | AI2: ='2_MechAdd_LowSeverity'!U2 | AJ2: ='2_MechAdd_ModSeverity'!S2 | AK2: ='2_MechAdd_ModSeverity'!T2 | AL2: ='2_MechAdd_ModSeverity'!U2 | AM2: ='2_MechAdd_HighSeverity'!S2 | AN2: ='2_MechAdd_HighSeverity'!T2 | AO2: ='2_MechAdd_HighSeverity'!U2 | AP2: ='2_MechAdd_LowSeverity'!V2 | AQ2: ='2_MechAdd_LowSeverity'!W2 | AR2: ='2_MechAdd_LowSeverity'!X2 | AS2: ='2_MechAdd_LowSeverity'!Y2 | AT2: ='2_MechAdd_ModSeverity'!W2 | AU2: ='2_MechAdd_ModSeverity'!X2 | AV2: ='2_MechAdd_ModSeverity'!Y2 | AW2: ='2_MechAdd_HighSeverity'!W2 | AX2: ='2_MechAdd_HighSeverity'!X2 | AY2: ='2_MechAdd_HighSeverity'!Y2 | AZ2: ='2_MechAdd_LowSeverity'!Z2 | BA2: ='2_MechAdd_LowSeverity'!AA2 | BB2: ='2_MechAdd_LowSeverity'!AB2 | BC2: ='2_MechAdd_LowSeverity'!AC2 | BD2: ='2_MechAdd_ModSeverity'!AA2 | BE2: ='2_MechAdd_ModSeverity'!AB2 | BF2: ='2_MechAdd_ModSeverity'!AC2 | BG2: ='2_MechAdd_HighSeverity'!AA2 | BH2: ='2_MechAdd_HighSeverity'!AB2 | BI2: ='2_MechAdd_HighSeverity'!AC2
